<?xml version="1.0"?>  
<sdf version="1.7">
  <model name='x1'>
      <enable_wind>1</enable_wind>
      <static>0</static>
      <link name='base_link'>
        <inertial>
          <pose>-0.00065 0 0.062 0 -0 0</pose>
          <mass>46.034</mass>
          <inertia>
            <ixx>0.613201</ixx>
            <ixy>0.0236401</ixy>
            <ixz>-0.1197</ixz>
            <iyy>0.7496</iyy>
            <iyz>0.00154411</iyz>
            <izz>2.0406</izz>
          </inertia>
        </inertial>
        <collision name='base_collision'>
          <pose>0 0 0.061875 0 -0 0</pose>
          <geometry>
            <box>
              <size>0.9874 0.5709 0.12375</size>
            </box>
          </geometry>
          <!--max_contacts>10</max_contacts>
          <surface>
            <contact>
              <ode/>
            </contact>
            <bounce/>
            <friction>
              <torsional>
                <ode/>
              </torsional>
              <ode/>
            </friction>
          </surface-->
        </collision>
        <!--collision name='base_collision_1'>
          <pose>0 0 0.185625 0 -0 0</pose>
          <geometry>
            <box>
              <size>0.78992 0.5709 0.12375</size>
            </box>
          </geometry>
          <max_contacts>10</max_contacts>
          <surface>
            <contact>
              <ode/>
            </contact>
            <bounce/>
            <friction>
              <torsional>
                <ode/>
              </torsional>
              <ode/>
            </friction>
          </surface>
        </collision-->
        <collision name='top_plate_collision'>
          <pose>0.0812 0 0.245 0 -0 0</pose>
          <geometry>
            <mesh>
              <uri>x1/x1 ugv - fortress param demo/1/meshes/top_plate.dae</uri>
            </mesh>
          </geometry>
          <!--max_contacts>10</max_contacts>
          <surface>
            <contact>
              <ode/>
            </contact>
            <bounce/>
            <friction>
              <torsional>
                <ode/>
              </torsional>
              <ode/>
            </friction>
          </surface-->
        </collision>
        <collision name='top_plate_collision_2'>
          <pose>0.0812 0 0.245 0 -0 0</pose>
          <geometry>
            <box>
              <size>0.32 0.41 0.09</size>
            </box>
          </geometry>
          <!--max_contacts>10</max_contacts>
          <surface>
            <contact>
              <ode/>
            </contact>
            <bounce/>
            <friction>
              <torsional>
                <ode/>
              </torsional>
              <ode/>
            </friction>
          </surface-->
        </collision>
        <visual name='base_visual'>
          <pose>0 0 0 0 0 -3.14159</pose>
          <geometry>
            <mesh>
              <uri>x1/x1 ugv - fortress param demo/1/meshes/chassis.dae</uri>
            </mesh>
          </geometry>
        </visual>
        <visual name='center_left_headlight_visual'>
          <pose>0.485766 0.0844 0.124431 0 0 -3.14159</pose>
          <geometry>
            <mesh>
              <uri>x1/x1 ugv - fortress param demo/1/meshes/headlight.dae</uri>
            </mesh>
          </geometry>
        </visual> -->
        <visual name='center_right_headlight_visual'>
          <pose>0.485766 -0.0844 0.124431 0 0 -3.14159</pose>
          <geometry>
            <mesh>
              <uri>x1/x1 ugv - fortress param demo/1/meshes/headlight.dae</uri>
            </mesh>
          </geometry>
        </visual>
        <visual name='left_headlight_visual'>
          <pose>0.461459 0.216803 0.124431 0 0 -3.14159</pose>
          <geometry>
            <mesh>
              <uri>x1/x1 ugv - fortress param demo/1/meshes/headlight.dae</uri>
            </mesh>
          </geometry>
        </visual>
        <visual name='marker_visual_1'>
          <pose>0.066047 0.212211 0.209188 -3.14159 1.57079 -1.60259</pose>
          <geometry>
            <mesh>
              <uri>x1/x1 ugv - fortress param demo/1/meshes/led.dae</uri>
            </mesh>
          </geometry>
        </visual>
        <visual name='marker_visual_2'>
          <pose>-0.066047 0.212211 0.209188 -3.14159 1.57079 -1.60259</pose>
          <geometry>
            <mesh>
              <uri>x1/x1 ugv - fortress param demo/1/meshes/led.dae</uri>
            </mesh>
          </geometry>
        </visual>
        <visual name='marker_visual_3'>
          <pose>-0.42493 0 0.209188 3.14159 1.57079 7e-06</pose>
          <geometry>
            <mesh>
              <uri>x1/x1 ugv - fortress param demo/1/meshes/led.dae</uri>
            </mesh>
          </geometry>
        </visual>
        <visual name='marker_visual_4'>
          <pose>-0.42493 0.13619 0.209188 3.14159 1.57079 7e-06</pose>
          <geometry>
            <mesh>
              <uri>x1/x1 ugv - fortress param demo/1/meshes/led.dae</uri>
            </mesh>
          </geometry>
        </visual>
        <visual name='marker_visual_5'>
          <pose>-0.42493 -0.13619 0.209188 3.14159 1.57079 7e-06</pose>
          <geometry>
            <mesh>
              <uri>x1/x1 ugv - fortress param demo/1/meshes/led.dae</uri>
            </mesh>
          </geometry>
        </visual>
        <visual name='right_headlight_visual'>
          <pose>0.461459 -0.216803 0.124431 0 0 -3.14159</pose>
          <geometry>
            <mesh>
              <uri>x1/x1 ugv - fortress param demo/1/meshes/headlight.dae</uri>
            </mesh>
          </geometry>
        </visual>
        <visual name='marker_visual_6'>
          <pose>0.066047 -0.212211 0.209188 3.14159 1.57079 1.60259</pose>
          <geometry>
            <mesh>
              <uri>x1/x1 ugv - fortress param demo/1/meshes/led.dae</uri>
            </mesh>
          </geometry>
        </visual>
        <visual name='marker_visual_7'>
          <pose>-0.066047 -0.212211 0.209188 3.14159 1.57079 1.60259</pose>
          <geometry>
            <mesh>
              <uri>x1/x1 ugv - fortress param demo/1/meshes/led.dae</uri>
            </mesh>
          </geometry>
        </visual>
        <visual name='top_plate_visual'>
          <pose>0.0812 0 0.245 0 -0 0</pose>
          <geometry>
            <mesh>
              <uri>x1/x1 ugv - fortress param demo/1/meshes/top_plate.dae</uri>
            </mesh>
          </geometry>
        </visual>
        <!-- <light name='left_light_source' type='spot'>
          <pose>0.514147 0.216803 0.18 3.14159 1.56859 0</pose>
          <attenuation>
            <range>2</range>
            <linear>0</linear>
            <constant>0.1</constant>
            <quadratic>0.0025</quadratic>
          </attenuation>
          <diffuse>0.8 0.8 0.5 1</diffuse>
          <specular>0.8 0.8 0.5 1</specular>
          <spot>
            <inner_angle>1</inner_angle>
            <outer_angle>1.1</outer_angle>
            <falloff>1</falloff>
          </spot>
          <direction>0 0 -1</direction>
        </light>
        <light name='center_left_light' type='spot'>
          <pose>0.538 0.0844 0.18 3.14159 1.56859 0</pose>
          <attenuation>
            <range>2</range>
            <linear>0</linear>
            <constant>0.1</constant>
            <quadratic>0.0025</quadratic>
          </attenuation>
          <diffuse>0.8 0.8 0.5 1</diffuse>
          <specular>0.8 0.8 0.5 1</specular>
          <spot>
            <inner_angle>1</inner_angle>
            <outer_angle>1.1</outer_angle>
            <falloff>1</falloff>
          </spot>
          <direction>0 0 -1</direction>
        </light>
        <light name='center_right_light' type='spot'>
          <pose>0.538 -0.0844 0.18 3.14159 1.56859 0</pose>
          <attenuation>
            <range>2</range>
            <linear>0</linear>
            <constant>0.1</constant>
            <quadratic>0.0025</quadratic>
          </attenuation>
          <diffuse>0.8 0.8 0.5 1</diffuse>
          <specular>0.8 0.8 0.5 1</specular>
          <spot>
            <inner_angle>1</inner_angle>
            <outer_angle>1.1</outer_angle>
            <falloff>1</falloff>
          </spot>
          <direction>0 0 -1</direction>
        </light>
        <light name='right_light_source' type='spot'>
          <pose>0.514147 -0.216803 0.18 3.14159 1.56859 0</pose>
          <attenuation>
            <range>2</range>
            <linear>0</linear>
            <constant>0.1</constant>
            <quadratic>0.0025</quadratic>
          </attenuation>
          <diffuse>0.8 0.8 0.5 1</diffuse>
          <specular>0.8 0.8 0.5 1</specular>
          <spot>
            <inner_angle>1</inner_angle>
            <outer_angle>1.1</outer_angle>
            <falloff>1</falloff>
          </spot>
          <direction>0 0 -1</direction>
        </light> -->
        <self_collide>0</self_collide>
        <enable_wind>1</enable_wind>
        <kinematic>0</kinematic>
        <sensor name="imu_sensor" type="imu">
      <always_on>true</always_on>
      <update_rate>100</update_rate>
      <visualize>true</visualize>
      <topic>imu</topic>
      <plugin filename="libgazebo_ros_imu_sensor.so" name="imu_plugin">
        <topicName>imu</topicName>
        <bodyName>imu_link</bodyName>
        <updateRateHZ>10.0</updateRateHZ>
        <gaussianNoise>0.0</gaussianNoise>
        <xyzOffset>0 0 0</xyzOffset>
        <rpyOffset>0 0 0</rpyOffset>
        <frameName>imu_link</frameName>
        <initialOrientationAsReference>false</initialOrientationAsReference>
      </plugin>
      <pose>0 0 0 0 0 0</pose>
    </sensor>
      </link>
      <link name='front_left_wheel'>
        <pose>0.256 0.2854 0.03282 0 -0 0</pose>
        <inertial>
          <mass>2.637</mass>
          <inertia>
            <ixx>0.02467</ixx>
            <ixy>0</ixy>
            <ixz>0</ixz>
            <iyy>0.04411</iyy>
            <iyz>0</iyz>
            <izz>0.02467</izz>
          </inertia>
          <pose>0 0 0 0 -0 0</pose>
        </inertial>
        <collision name='collision'>
          <pose>0 0 0 -1.57079 0 0</pose>
          <geometry>
            <cylinder>
              <length>0.1143</length>
              <radius>0.1651</radius>
            </cylinder>
          </geometry>
          <!--surface>
            <friction>
              <ode>
                <mu>0.1</mu>
              </ode>
              <torsional>
                <ode/>
              </torsional>
            </friction>
            <contact>
              <ode/>
            </contact>
            <bounce/>
          </surface>
          <max_contacts>10</max_contacts-->
        </collision>
        <visual name='visual'>
          <geometry>
            <mesh>
              <uri>x1/x1 ugv - fortress param demo/1/meshes/wheel.dae</uri>
            </mesh>
          </geometry>
        </visual>
        <self_collide>0</self_collide>
        <enable_wind>1</enable_wind>
        <kinematic>0</kinematic>
      </link>
      <joint name='front_left_wheel_joint' type='revolute'>
        <parent>base_link</parent>
        <child>front_left_wheel</child>
        <axis>
          <xyz>0 1 0</xyz>
          <!--limit>
            <lower>-1.79769e+308</lower>
            <upper>1.79769e+308</upper>
          </limit-->
          <!--dynamics>
            <spring_reference>0</spring_reference>
            <spring_stiffness>0</spring_stiffness>
          </dynamics-->
        </axis>
      </joint>
      <link name='front_right_wheel'>
        <pose>0.256 -0.2854 0.03282 0 -0 0</pose>
        <inertial>
          <mass>2.637</mass>
          <inertia>
            <ixx>0.02467</ixx>
            <ixy>0</ixy>
            <ixz>0</ixz>
            <iyy>0.04411</iyy>
            <iyz>0</iyz>
            <izz>0.02467</izz>
          </inertia>
          <pose>0 0 0 0 -0 0</pose>
        </inertial>
        <collision name='collision'>
          <pose>0 0 0 -1.57079 0 0</pose>
          <geometry>
            <cylinder>
              <length>0.1143</length>
              <radius>0.1651</radius>
            </cylinder>
          </geometry>
          <!--surface>
            <friction>
              <ode>
                <mu>0.1</mu>
              </ode>
              <torsional>
                <ode/>
              </torsional>
            </friction>
            <contact>
              <ode/>
            </contact>
            <bounce/>
          </surface>
          <max_contacts>10</max_contacts-->
        </collision>
        <visual name='visual'>
          <geometry>
            <mesh>
              <uri>x1/x1 ugv - fortress param demo/1/meshes/wheel.dae</uri>
            </mesh>
          </geometry>
        </visual>
        <self_collide>0</self_collide>
        <enable_wind>1</enable_wind>
        <kinematic>0</kinematic>
      </link>
      <joint name='front_right_wheel_joint' type='revolute'>
        <child>front_right_wheel</child>
        <parent>base_link</parent>
        <axis>
          <xyz>0 1 0</xyz>
          <!--limit>
            <lower>-1.79769e+308</lower>
            <upper>1.79769e+308</upper>
          </limit-->
          <!--dynamics>
            <spring_reference>0</spring_reference>
            <spring_stiffness>0</spring_stiffness>
          </dynamics-->
        </axis>
      </joint>
      <link name='rear_left_wheel'>
        <pose>-0.256 0.2854 0.03282 0 -0 0</pose>
        <inertial>
          <mass>2.637</mass>
          <inertia>
            <ixx>0.02467</ixx>
            <ixy>0</ixy>
            <ixz>0</ixz>
            <iyy>0.04411</iyy>
            <iyz>0</iyz>
            <izz>0.02467</izz>
          </inertia>
          <pose>0 0 0 0 -0 0</pose>
        </inertial>
        <collision name='collision'>
          <pose>0 0 0 -1.57079 0 0</pose>
          <geometry>
            <cylinder>
              <length>0.1143</length>
              <radius>0.1651</radius>
            </cylinder>
          </geometry>
          <!--surface>
            <friction>
              <ode>
                <mu>0.1</mu>
              </ode>
              <torsional>
                <ode/>
              </torsional>
            </friction>
            <contact>
              <ode/>
            </contact>
            <bounce/>
          </surface>
          <max_contacts>10</max_contacts-->
        </collision>
        <visual name='visual'>
          <geometry>
            <mesh>
              <uri>x1/x1 ugv - fortress param demo/1/meshes/wheel.dae</uri>
            </mesh>
          </geometry>
        </visual>
        <self_collide>0</self_collide>
        <enable_wind>1</enable_wind>
        <kinematic>0</kinematic>
      </link>
      <joint name='rear_left_wheel_joint' type='revolute'>
        <parent>base_link</parent>
        <child>rear_left_wheel</child>
        <axis>
          <xyz>0 1 0</xyz>
          <!--limit>
            <lower>-1.79769e+308</lower>
            <upper>1.79769e+308</upper>
          </limit-->
          <!--dynamics>
            <spring_reference>0</spring_reference>
            <spring_stiffness>0</spring_stiffness>
          </dynamics-->
        </axis>
      </joint>
      <link name='rear_right_wheel'>
        <pose>-0.256 -0.2854 0.03282 0 -0 0</pose>
        <inertial>
          <mass>2.637</mass>
          <inertia>
            <ixx>0.02467</ixx>
            <ixy>0</ixy>
            <ixz>0</ixz>
            <iyy>0.04411</iyy>
            <iyz>0</iyz>
            <izz>0.02467</izz>
          </inertia>
          <pose>0 0 0 0 -0 0</pose>
        </inertial>
        <collision name='collision'>
          <pose>0 0 0 -1.57079 0 0</pose>
          <geometry>
            <cylinder>
              <length>0.1143</length>
              <radius>0.1651</radius>
            </cylinder>
          </geometry>
          <!--surface>
            <friction>
              <ode>
                <mu>0.1</mu>
              </ode>
              <torsional>
                <ode/>
              </torsional>
            </friction>
            <contact>
              <ode/>
            </contact>
            <bounce/>
          </surface>
          <max_contacts>10</max_contacts-->
        </collision>
        <visual name='visual'>
          <geometry>
            <mesh>
              <uri>x1/x1 ugv - fortress param demo/1/meshes/wheel.dae</uri>
            </mesh>
          </geometry>
        </visual>
        <self_collide>0</self_collide>
        <enable_wind>1</enable_wind>
        <kinematic>0</kinematic>
      </link>
      <joint name='rear_right_wheel_joint' type='revolute'>
        <child>rear_right_wheel</child>
        <parent>base_link</parent>
        <axis>
          <xyz>0 1 0</xyz>
          <!--limit>
            <lower>-1.79769e+308</lower>
            <upper>1.79769e+308</upper>
          </limit-->
          <!--dynamics>
            <spring_reference>0</spring_reference>
            <spring_stiffness>0</spring_stiffness>
          </dynamics-->
        </axis>
      </joint>
      <pose>-0.089413 -0.405844 0 0 -0 0</pose>

      <link name="os1_sensor_link">
        <pose>0.4 0 0.285 0 0 0</pose>
        <inertial>
          <mass>0.1</mass>
          <inertia>
            <ixx>0.000090623</ixx>
            <iyy>0.000090623</iyy>
            <izz>0.000091036</izz>
            <ixy>0</ixy>
            <ixz>0</ixz>
            <iyz>0</iyz>
          </inertia>
        </inertial>
        <collision name="top_collision">
          <geometry>
            <cylinder>
              <radius>0.04267</radius>
              <length>0.07357</length>
            </cylinder>
          </geometry>
        </collision>
        <visual name="top_visual">
          <pose>0 0 -0.0376785 0 0 1.5707</pose>
          <geometry>
            <mesh>
              <uri>model://velodyne_hdl32/meshes/velodyne_top.dae</uri>
            </mesh>
          </geometry>
        </visual>
        <sensor type="ray" name="lase_scan">
          <pose>0 0 -0.004645 0 0 0</pose>
          <visualize>false</visualize>
          <update_rate>10</update_rate>
          <ray>
            <scan>
              <horizontal>
                <samples>512</samples>
                <resolution>1</resolution>
                <min_angle>-3.14159</min_angle>
                <max_angle>3.14159</max_angle>
              </horizontal>
              <vertical>
                <samples>16</samples>
                <resolution>1</resolution>
                <min_angle>-0.2897247</min_angle>
                <max_angle>0.2897247</max_angle>
              </vertical>
            </scan>
            <range>
              <min>1</min>
              <max>122</max>
              <resolution>0.012</resolution>
            </range>
            <noise>
              <type>gaussian</type>
              <mean>0.0</mean>
              <stddev>0.0</stddev>
            </noise>
          </ray>
          <plugin name="gazebo_ros_laser_controller" filename="libgazebo_ros_velodyne_laser.so">

            <topicName>os1_cloud_node_points</topicName>
            <frameName>os1_sensor</frameName>
            <min_range>1</min_range>
            <max_range>122.0</max_range>
            <gaussianNoise>0.008</gaussianNoise>  
          </plugin>
        </sensor>
      </link>
      <joint name='joint' type='fixed'>
        <child>os1_sensor_link</child>
        <parent>base_link</parent>
        <pose> 0 0 0 0 0 0</pose>
      </joint>
      
      <plugin name="gps_controller_siar" filename="libplugin_gazebo_ros_gps.so">
        <alwaysOn>true</alwaysOn>
        <updateRate>5.0</updateRate>
        <bodyName>base_link</bodyName>
        <robotBaseFrame>base_link</robotBaseFrame>
        <!-- <frameId>siar/base_link</frameId> -->
        <topicName>gps</topicName>
        <velocityTopicName>gps_velocity</velocityTopicName>
        <drift>5.0 5.0 5.0</drift>
        <gaussianNoise>0.1 0.1 0.1</gaussianNoise>
        <velocityDrift>0 0 0</velocityDrift>
        <velocityGaussianNoise>0.1 0.1 0.1</velocityGaussianNoise>
        <referenceLatitude>49.9</referenceLatitude>
        <referenceLongitude>8.9</referenceLongitude>
        <referenceHeading>0</referenceHeading>
        <referenceAltitude>0</referenceAltitude>
    </plugin>
    
      <plugin name="diffdrive_plugin_multi_wheel" filename="libplugin_diffdrive_plugin_multi_wheel.so">
    
        <!-- Plugin update rate in Hz -->
        <updateRate>10</updateRate>
        <!-- Name of left joint, defaults to `left_joint` -->
        <!--leftJoint>base_link_left_wheel_joint</leftJoint-->
        <leftJoints>rear_left_wheel_joint front_left_wheel_joint</leftJoints>
        <!-- Name of right joint, defaults to `right_joint` -->
        <!--rightJoint>base_link_right_wheel_joint</rightJoint-->
        <rightJoints>rear_right_wheel_joint front_right_wheel_joint</rightJoints>
        <!-- The distance from the center of one wheel to the other, in meters, defaults to 0.34 m -->
        <wheelSeparation>0.6380</wheelSeparation>
        <!-- Diameter of the wheels, in meters, defaults to 0.15 m -->
        <wheelDiameter>0.2410</wheelDiameter>
        <!-- Wheel acceleration, in rad/s^2, defaults to 0.0 rad/s^2 -->
        <!--wheelAcceleration>1.0</wheelAcceleration-->
        <!-- Maximum torque which the wheels can produce, in Nm, defaults to 5 Nm -->
        <torque>20</torque>
        <!-- Topic to receive geometry_msgs/Twist message commands, defaults to `cmd_vel` -->
        <commandTopic>cmd_vel</commandTopic>
        <!-- Topic to publish nav_msgs/Odometry messages, defaults to `odom` -->
        <odometryTopic>odom</odometryTopic>
        <!-- Odometry frame, defaults to `odom` -->
        <odometryFrame>odom</odometryFrame>
        <!-- Robot frame to calculate odometry from, defaults to `base_footprint` -->
        <robotBaseFrame>base_link</robotBaseFrame>
        <!-- Odometry source, 0 for ENCODER, 1 for WORLD, defaults to WORLD -->
        <!--odometrySource>1</odometrySource-->
        <!-- Set to true to publish transforms for the wheel links, defaults to false -->
        <publishWheelTF>true</publishWheelTF>
        <!-- Set to true to publish transforms for the odometry, defaults to true -->
        <publishOdometryTf>true</publishOdometryTf>
        <!-- Set to true to publish sensor_msgs/JointState on /joint_states for the wheel joints, defaults to false -->
        <!--publishWheelJointState>true</publishWheelJointState-->
        <!-- Set to true to swap right and left wheels, defaults to true -->
        <publishOdometryMsg>false</publishOdometryMsg>
        <!--publishOdomTF>true</publishOdomTF-->
        <!--rosDebugLevel>na</rosDebugLevel-->
        <!--odometrySource>1</odometrySource-->
      
    </plugin>
    <gazebo>
    <plugin name="diffdrive_plugin_multi_wheel" filename="libplugin_diffdrive_plugin_multi_wheel.so">
    
    <!-- Plugin update rate in Hz -->
    <updateRate>10</updateRate>
    <!-- Name of left joint, defaults to `left_joint` -->
    <!--leftJoint>base_link_left_wheel_joint</leftJoint-->
    <leftJoints>rear_left_wheel_joint front_left_wheel_joint</leftJoints>
    <!-- Name of right joint, defaults to `right_joint` -->
    <!--rightJoint>base_link_right_wheel_joint</rightJoint-->
    <rightJoints>rear_right_wheel_joint front_right_wheel_joint</rightJoints>
    <!-- The distance from the center of one wheel to the other, in meters, defaults to 0.34 m -->
    <wheelSeparation>0.6380</wheelSeparation>
    <!-- Diameter of the wheels, in meters, defaults to 0.15 m -->
    <wheelDiameter>0.2410</wheelDiameter>
    <!-- Wheel acceleration, in rad/s^2, defaults to 0.0 rad/s^2 -->
    <!--wheelAcceleration>1.0</wheelAcceleration-->
    <!-- Maximum torque which the wheels can produce, in Nm, defaults to 5 Nm -->
    <torque>20</torque>
    <!-- Topic to receive geometry_msgs/Twist message commands, defaults to `cmd_vel` -->
    <commandTopic>cmd_vel</commandTopic>
    <!-- Topic to publish nav_msgs/Odometry messages, defaults to `odom` -->
    <odometryTopic>odom</odometryTopic>
    <!-- Odometry frame, defaults to `odom` -->
    <odometryFrame>odom</odometryFrame>
    <!-- Robot frame to calculate odometry from, defaults to `base_footprint` -->
    <robotBaseFrame>base_link</robotBaseFrame>
    <!-- Odometry source, 0 for ENCODER, 1 for WORLD, defaults to WORLD -->
    <!--odometrySource>1</odometrySource-->
    <!-- Set to true to publish transforms for the wheel links, defaults to false -->
    <publishWheelTF>true</publishWheelTF>
    <!-- Set to true to publish transforms for the odometry, defaults to true -->
    <publishOdometryTf>true</publishOdometryTf>
    <!-- Set to true to publish sensor_msgs/JointState on /joint_states for the wheel joints, defaults to false -->
    <!--publishWheelJointState>true</publishWheelJointState-->
    <!-- Set to true to swap right and left wheels, defaults to true -->
    <publishOdometryMsg>false</publishOdometryMsg>
    <!--publishOdomTF>true</publishOdomTF-->
    <!--rosDebugLevel>na</rosDebugLevel-->
    <!--odometrySource>1</odometrySource-->
  </plugin>
  </gazebo>

  
    </model>
</sdf>
